Workbook

Sheet Trophies & Lore
A1: HEAT CAMPAIGN — LORE & TROPHY REGISTRY
A3: LEAGUE NAME | B3: Calore 1 (C1)
A4: GOVERNING BODY | B4: Federazione Internazionale delle Competizioni di Calore (FICC)
A5: FOUNDED | B5: 1961 — following a controversial rules dispute with the establishment of the "Intercontinental Race Series" (IRS)
A6: LEAGUE MOTTO | B6: Win at All Costs
A8: DRIVER'S TROPHY | B8: The Axle Carbone Trophy
A9: AWARDED TO | B9: The season's top individual driver — Driver's Championship winner
A10: ABOUT AXLE CARBONE | B10: Axle Carbone was born in 1927 in a small garage town outside Lyon, France, the son of a mechanic who never once let him sit still. By nineteen he was racing anything with an engine; by twenty-four he had won back-to-back Intercontinental championships in the IRS's founding seasons of 1950 and 1951. He was famous for two things: an uncanny ability to nurse a damaged car to the finish line, and a complete refusal to pit when the strategy called for it. "The track is where races are won," he said once. "The pits are where they are lost." He retired abruptly after the 1955 season with four championships to his name — some say after a falling-out with the IRS stewards over a disputed penalty at the Monte Circuit finale, a race he crossed first but was stripped of on a technicality. He never spoke publicly about it. After a rules dispute at the end of the 1960 season, a contingent of drivers and teams broke off from IRS and created the Calore 1 (C1) racing series. They named the driver's championship trophy the Alex Carbnone Cup. The trophy carries his initials — A.C. — stamped into the base in carbon steel. Carbone, having bitterly retired in 1955, agreed to join C1, lining up on the grid as a worldwide legend.
A12: CONSTRUCTOR'S TROPHY | B12: The Lucca Pistone Constructor's Cup
A13: AWARDED TO | B13: The top team each season — Constructor's Championship winner
A14: ABOUT LUCCA PISTONE | B14: Lucca Pistone never drove a competitive lap in his life, and he would have been the first to tell you so. An Italian engineer from Forli, he arrived at the ISR's inaugural season in 1950 as a car builder — and within three years his cars had won everything worth winning. His philosophy was obsessive: every component had a purpose, every gram of weight had to earn its place, and the piston was his personal symbol — he saw it as the essence of engineering, raw power and force that is the key component to an engine. He built cars for Axle Carbone's championship runs and later for three other title winners. He died in 1960 during a pre-season test when a fuel line failed — characteristically, the investigation found the failure was in a component he had explicitly flagged for replacement the week before and been overruled on by the team's financiers. The Constructor's Cup was renamed in his honor that same year. Teams who win it receive a trophy fitted with a piston atop it.
A16: BACKSTORY NOTE | B16: Pistone built Carbone's championship cars. The two trophies exist in the same universe — their stories are inseparable. Winning both in the same season is considered the World Racing Grand Slam, an achievement no driver or team has ever managed.

Sheet 1961 Driver Lineup
A1: Player | B1: Driver | C1: Car Color | D1: Team Name | E1: Backstory
A2: Eric Maras | B2: Anders Snabb | C2: Silver | D2: FjordFart | E2: Anders grew up a car fanatic. As a child, all he played with were toy cars. He used to race little derby cars with his friends, often throwing massive fits if his cars did not win. He started karting at the age of four, and he won the Swedish Karting Championship as a nine year old. His father and mother both served as an inspiration for his racing career. They both met working as mechanics in a local garage in the outskirts of Stockholm. Anders has competed in many regional race series, including rally car. He is excited for his rookie season in the World Grand Prix Series, and he brings an icy cool persona that sometimes shoots up in flames if he doesn't win.
A3: Daniel Yun | B3: Count Dragula | C3: Black | D3: Blüd Bath | E3: Hailing from the gloomy forests of Transmissionylvania, Count Dragula was groomed by his father, Baron Victorque of Carovia to continue the legacy of Transmissionylvania's prestigious racing tradition. Dragula is an aggressive, cunning driver who's out for blood and eager to prove himself in the international circuit after dominating the Transmissionylvanian Blood Chalice the last three years running. He enjoys long walks in the graveyard, hates garlic, and donates all his winnings to and volunteers at animal shelters in his hometown
A4: Evan Keane | B4: Horace Bauer | C4: Blue | D4: Vroom | E4: Horace raced shopping carts down parking garage ramps for a decade, and F1 scouts figured anyone who could hit 35 mph in a cart with 2 bad wheels deserved a real car.
A5: Blake Roberts | B5: Jean Girard | C5: Green | D5: Perrier | E5: My name is Jean Girard and I am a racing-car driver just like you except I am from Formula Un. I am the greatest one in the whole world. I have been following your career with great interest, Monsieur Bobby.
A6: Dallas Manaker | B6: "Caveman" Dale Mercer | C6: Yellow | D6: Team Neandrathal | E6: Dale Mercer didn’t choose racing—racing happened to him the same way spilled beer “happens” to a carpet: suddenly, everywhere, and you can’t pretend it didn’t. He “learned” driving from late-night YouTube, a questionable steering wheel he bought off a guy who claimed it was “basically brand new,” and a lifelong belief that the fastest line is the one that makes other people blink first. His crew says he’s smooth; Dale says smooth is for people who don’t enjoy the sound of tires protesting. Every night he straps in like a menace, shouts nonsense at the speedometer, and treats broken tactics as “character building.” Hunt-level swagger, but with more dirt under the nails and less patience for anyone who says, “Maybe lift a bit.”
A7: Rosaria Thea Cali | B7: Circe Belladonna | C7: Purple | D7: Piggie | E7: Circe was once peacefully living on her private island, turning rude men into pigs and enjoying a normal, healthy amount of wine, when she discovered an even better hobby: ruining men’s confidence on the racetrack. Rivals claim her purple car smells faintly of herbs, seawater, and bad decisions. Circe denies using magic during races, though several drivers have mysteriously started oinking after trying to pass her. Her goal this season is simple: win the championship, humiliate the arrogant, and maybe turn one or two team principals into livestock if the mood is right.
A8: Dan Newcomer | B8: Mr. Pink | C8: Orange | D8: Team No Tip | E8: Mr. Pink was robbing a diamond store when, during the getaway, he ended up on a race track.
A9: Kristen Vassalli | B9: Chico Suave | C9: Red | D9: Vassalligator | E9: Chico doesn't know how to drive because he is a dog, but it doesn't seem that hard. Plus, his humans said he'd be paid in cheese if he wins, so might as well try! A lack of thumbs may or may not impede his performance, but his crew are an insanely cracked set of hackers and makers and they've been modding up a dog-driveable car to help him cross the finish line - first. Since he's so small, his crew is hopeful their teeny tiny dog-driveable car can shave a ton of weight and zoom past his (speciesist) competitors.

Sheet 1961 Season Overview
A1: HEAT: PEDAL TO THE METAL — CAMPAIGN SEASON OVERVIEW
A3: SEASON INFORMATION
A4: Season number | B4: 1
A5: Races this season | B5: 4
A6: Upgrade slots this season | B6: 3
A7: Track selection method | B7: FICC Vote
A8: Mid-season break after race # | B8: 2
A9: Legends | B9: No
A10: Base Team Budget | B10: 15000000
A12: RACE SCHEDULE
A13: Race # | B13: Track
A14: 1 | B14: Mexico
A15: 2 | B15: Germany
A16: 3 | B16: South Africa
A17: 4 | B17: France

Sheet 1961 Technical Regulations
A1: Regulation Name | B1: Regulation Type | C1: Explanation | D1: Expiration
A2: Upgrade Availability | B2: Restriction | C2: No upgrades from the S, A, and B tiers are allowed - they have not been developed yet | D2: Expires after the 1961 season - a vote will be held by the FICC
A3: Upgrade Availability | B3: Restriction | C3: Each team can only have three upgrade cards | D3: Expires after the 1961 season - a vote will be held by the FICC
A4: Upgrade Availability | B4: Restriction | C4: Each team can only have one of each upgrade type | D4: Expires after the 1961 season - a vote will be held by the FICC
A5: Driver Funding | B5: Funding | C5: Each team is given 15 million dollars to develop their car | D5: Expires after the 1961 season - a vote will be held by the FICC
A6: Mid-Season Catch-up | B6: Funding | C6: The bottom 3 teams in the standings at the middle of the season break are awarded an additional 3 million in funding and can swap up to two of their upgrades | D6: Expires after the 1961 season - a vote will be held by the FICC
A7: Sponsor Budget | B7: Funding | C7: Sponsors can fund up to 5 million dollars per team | D7: Expires after the 1961 season - a vote will be held by the FICC
A8: Fuel Type | B8: Restriction | C8: Only standard fuel is allowed for vehicles - all vehicles must run the same fuel | D8: Expires after the 1961 season - a vote will be held by the FICC
A9: Champion's Gold Wrench Veto | B9: Benefit | C9: The champion of a season can veto one new FICC rule proposal - this includes changes to an existing rule or a new rule | D9: Expires after the 1962 season - a vote will be held by the FICC
A10: Post-Season Funding Award | B10: Funding | C10: TBD - after the season, it must be decided how funding will be awarded to teams in the 1962 season | D10: N/A
A11: Team Car Allowance | B11: Team | C11: Each team can only enter one car for the season | D11: Expires after the 1961 season - a vote will be held by the FICC
A12: Budget Overflow | B12: Funding | C12: Each team can retain all of the funding they did not spend in this season as a carryover to the next season | D12: Expires after the 1961 season - a vote will be held by the FICC
... A15: Missed Race | B15: Scoring | C15: If a driver misses a race, a reserve legend will take their place. The legend will only earn half points rounded down for position | D15: Expires after the 1961 season - a vote will be held by the FICC

Sheet FICC Backlog
A1: Federazione Internazionale delle Competizioni di Calore — RULES BACKLOG
A2: Proposals voted on each off-season by the FICC. Simple majority wins. Champion holds one Golden Wrench veto per off-season.
A3: Each driver can propose up to one new regulation at the conclusion of the season. Drivers then vote on these rules. Rules must have 6/8 votes to pass
A4: Existing regulations that need to be renewed will also be voted on. These regulations will also need 6/8 votes to pass.
A5: Driver Name | B5: Proposed Regulation Name | C5: Regulation Type | D5: Explanation | E5: Expiration
A6: {=INDEX(DriverLineup[Driver], ROW()-ROW($A$6)+1)} -> Anders Snabb | B6: Turbo Ban | C6: Detriment | D6: Turbos are not allowed | E6: End of 1962 season
A7: {=INDEX(DriverLineup[Driver], ROW()-ROW($A$6)+1)} -> Count Dragula | B7: Costume Rule | C7: Benefit | D7: If your driver comes dressed up in full costume, you get one free boost for the race. Stackable with any other boost. Must have at least top and bottom and one accessory. | E7: End of 1962 season
A8: {=INDEX(DriverLineup[Driver], ROW()-ROW($A$6)+1)} -> Horace Bauer | E8: End of 1962 season
A9: {=INDEX(DriverLineup[Driver], ROW()-ROW($A$6)+1)} -> Jean Girard | E9: End of 1962 season
A10: {=INDEX(DriverLineup[Driver], ROW()-ROW($A$6)+1)} -> "Caveman" Dale Mercer | E10: End of 1962 season
A11: {=INDEX(DriverLineup[Driver], ROW()-ROW($A$6)+1)} -> Circe Belladonna | B11: Chicane easment | C11: Assistance | D11: If you spin out at a chicane, for an additional stress you can pass the corners by only one space. | E11: End of 1962 season
A12: {=INDEX(DriverLineup[Driver], ROW()-ROW($A$6)+1)} -> Mr. Pink | E12: End of 1962 season
A13: {=INDEX(DriverLineup[Driver], ROW()-ROW($A$6)+1)} -> Chico Suave | B13: Stress transfer | C13: Detriment | D13: When you acquire a stress card, roll one die and if you roll a 6, the car in first gets 2 new stress cards. The car that spun out does not acquire any stress | E13: End of 1962 season
B19: Qualifying round | C19: Season 2+ | D19: Short time-attack before each race sets the starting grid. Pole earns +1 championship point. | E19: Pending
B20: Sprint race | C20: Season 2+ | D20: One lap only, half points awarded. Run as race 1 of a double-header weekend. | E20: Pending
B21: Fastest lap point | C21: Any season | D21: One bonus point to the driver with the fastest individual lap each race. | E21: Pending
B22: Reverse grid finale | C22: Season 3+ | D22: Final race of the season starts in reverse championship order. | E22: Pending
B23: Weather cards | C23: Season 3+ | D23: Secret card drawn at race start affects which upgrade types are advantaged that race. | E23: Pending
B24: Upgrade contraband | C24: Any season | D24: FICC votes to ban a specific upgrade type for one full season. | E24: Pending
B25: Legend inclusion | C25: Any season | D25: A Legend car enters, controlled by last season's last-place finisher. | E25: Pending
B26: Rookie bonus card | C26: Any season | D26: New drivers get a one-time 'Rookie Rage' powerful card but score 80% points in season 1. | E26: Pending
B27: Rival race | C27: Season 3+ | D27: Two drivers with closest head-to-head record compete in a bonus duel race. | E27: Pending
B28: Driver market | C28: Season 2+ | D28: At season end, drivers may trade one upgrade card by mutual agreement. | E28: Pending

Sheet 1961 Championship Standings
A1: DRIVER'S CHAMPIONSHIP — THE AXLE CARBONE TROPHY
A4: Driver | B4: Team | C4: Race 1: Mexico | D4: Race 2: Germany | E4: Race 3: South Africa | F4: Race 4: France | G4: Total Points | H4: Position
A5: {=INDEX(DriverLineup[Driver], ROW()-ROW($A$5)+1)} -> Anders Snabb | B5: {=INDEX(DriverLineup[Team Name], ROW()-ROW($A$5)+1)} -> FjordFart | C5: 3 | D5: 2 | G5: {=SUMPRODUCT(XLOOKUP($C5:$F5, PointLookup[Position], PointLookup[Points], 0))} -> 10 | H5: =RANK(G5,G$5:G$12,0) -> 2
A6: {=INDEX(DriverLineup[Driver], ROW()-ROW($A$5)+1)} -> Count Dragula | B6: {=INDEX(DriverLineup[Team Name], ROW()-ROW($A$5)+1)} -> Blüd Bath | C6: 2 | D6: 4 | G6: {=SUMPRODUCT(XLOOKUP($C6:$F6, PointLookup[Position], PointLookup[Points], 0))} -> 9 | H6: =RANK(G6,G$5:G$12,0) -> 3
A7: {=INDEX(DriverLineup[Driver], ROW()-ROW($A$5)+1)} -> Horace Bauer | B7: {=INDEX(DriverLineup[Team Name], ROW()-ROW($A$5)+1)} -> Vroom | C7: 4 | D7: 5 | G7: {=SUMPRODUCT(XLOOKUP($C7:$F7, PointLookup[Position], PointLookup[Points], 0))} -> 5 | H7: =RANK(G7,G$5:G$12,0) -> 4
A8: {=INDEX(DriverLineup[Driver], ROW()-ROW($A$5)+1)} -> Jean Girard | B8: {=INDEX(DriverLineup[Team Name], ROW()-ROW($A$5)+1)} -> Perrier | C8: 1 | D8: 1 | G8: {=SUMPRODUCT(XLOOKUP($C8:$F8, PointLookup[Position], PointLookup[Points], 0))} -> 18 | H8: =RANK(G8,G$5:G$12,0) -> 1
A9: {=INDEX(DriverLineup[Driver], ROW()-ROW($A$5)+1)} -> "Caveman" Dale Mercer | B9: {=INDEX(DriverLineup[Team Name], ROW()-ROW($A$5)+1)} -> Team Neandrathal | C9: 7 | D9: 3 | G9: {=SUMPRODUCT(XLOOKUP($C9:$F9, PointLookup[Position], PointLookup[Points], 0))} -> 4 | H9: =RANK(G9,G$5:G$12,0) -> 5
A10: {=INDEX(DriverLineup[Driver], ROW()-ROW($A$5)+1)} -> Circe Belladonna | B10: {=INDEX(DriverLineup[Team Name], ROW()-ROW($A$5)+1)} -> Piggie | C10: 6 | D10: 8 | G10: {=SUMPRODUCT(XLOOKUP($C10:$F10, PointLookup[Position], PointLookup[Points], 0))} -> 1 | H10: =RANK(G10,G$5:G$12,0) -> 7
A11: {=INDEX(DriverLineup[Driver], ROW()-ROW($A$5)+1)} -> Mr. Pink | B11: {=INDEX(DriverLineup[Team Name], ROW()-ROW($A$5)+1)} -> Team No Tip | C11: 5 | D11: 7 | G11: {=SUMPRODUCT(XLOOKUP($C11:$F11, PointLookup[Position], PointLookup[Points], 0))} -> 2 | H11: =RANK(G11,G$5:G$12,0) -> 6
A12: {=INDEX(DriverLineup[Driver], ROW()-ROW($A$5)+1)} -> Chico Suave | B12: {=INDEX(DriverLineup[Team Name], ROW()-ROW($A$5)+1)} -> Vassalligator | C12: 8 | D12: 6 | G12: {=SUMPRODUCT(XLOOKUP($C12:$F12, PointLookup[Position], PointLookup[Points], 0))} -> 1 | H12: =RANK(G12,G$5:G$12,0) -> 7
A14: Position | B14: Points
A15: 1 | B15: 9
A16: 2 | B16: 6
A17: 3 | B17: 4
A18: 4 | B18: 3
A19: 5 | B19: 2
A20: 6 | B20: 1
A21: 7 | B21: 0
A22: 8 | B22: 0
A23: 0 | B23: 0

Sheet Inventory
A1: Type | B1: Part Number | C1: Effect | D1: Count Available | E1: Tier | F1: Cost
A2: 4 Wheel Drive | B2: 1 | D2: 2 | E2: A | F2: 15000000
A3: 4 Wheel Drive | B3: 2 | D3: 2 | E3: S | F3: 18000000
A4: 4 Wheel Drive | B4: 3 | D4: 2 | E4: C | F4: 7000000
A5: Body | B5: 4 | D5: 2 | E5: C | F5: 6000000
A6: Body | B6: 5 | D6: 2 | E6: B | F6: 10000000
A7: Body | B7: 6 | D7: 2 | E7: D | F7: 4000000
A8: Brakes | B8: 7 | D8: 2 | E8: F | F8: 1000000
A9: Brakes | B9: 8 | D9: 2 | E9: C | F9: 6500000
A10: Brakes | B10: 9 | D10: 2 | E10: C | F10: 6500000
A11: Brakes | B11: 10 | D11: 2 | E11: B | F11: 10000000
A12: Cooling System | B12: 11 | D12: 2 | E12: B | F12: 10000000
A13: Cooling System | B13: 12 | D13: 2 | E13: C | F13: 7500000
... A17: RPM | B17: 16 | D17: 2 | E17: C | F17: 6500000
A18: Heat | B18: 17 | D18: 2 | E18: x | F18: x
A19: Body | B19: 18 | D19: 2 | E19: C | F19: 6000000
A20: Body | B20: 19 | D20: 2 | E20: C | F20: 7000000
A21: Body | B21: 20 | D21: 2 | E21: C | F21: 7000000
A22: Cooling System | B22: 21 | D22: 2 | E22: B | F22: 10000000
A23: Fuel | B23: 22 | C23: 2 [Salvage 2] | D23: 2 | E23: D | F23: 5000000
A24: Fuel | B24: 23 | C24: "+ [1 Cooldown, Salvage 2] " | D24: 2 | E24: C | F24: 7500000
A25: Gas Pedal | B25: 24 | D25: 2 | E25: C | F25: 6000000
A26: Gas Pedal | B26: 25 | D26: 2 | E26: C | F26: 6500000
A27: Gas Pedal | B27: 26 | D27: 2 | E27: B | F27: 9000000
A28: Gas Pedal | B28: 27 | D28: 2 | E28: C | F28: 7000000
A29: Gas Pedal | B29: 28 | D29: 2 | E29: C | F29: 7500000
A30: RPM | B30: 29 | D30: 2 | E30: B | F30: 11000000
A31: RPM | B31: 30 | D31: 2 | E31: C | F31: 6000000
A32: RPM | B32: 31 | D32: 2 | E32: B | F32: 11000000
A33: Suspension | B33: 32 | D33: 2 | E33: C | F33: 8000000
A34: Suspension | B34: 33 | D34: 2 | E34: B | F34: 10000000
A35: Suspension | B35: 34 | D35: 2 | E35: B | F35: 11000000
A36: Suspension | B36: 35 | D36: 2 | E36: C | F36: 8000000
... A44: Turbo Charger | B44: 43 | D44: 2 | E44: A | F44: 15000000
A45: Wings | B45: 44 | C45: 4 [1 Heat, Scrap 2, +2 Corner Speed Limit] | D45: 2 | E45: B | F45: 11000000
A46: Wings | B46: 45 | C46: 3 [1 Heat, Scrap 2, +2 Corner Speed Limit] | D46: 2 | E46: B | F46: 10000000
A47: Wings | B47: 46 | C47: 6 [2 Heat, +3 Corner Speed Limit] | D47: 2 | E47: D | F47: 5000000
A48: 4 Wheel Drive | B48: 47 | D48: 2 | E48: B | F48: 12000000
A49: Heat | B49: 48 | D49: 2 | E49: x | F49: x
A50: Air Intake | B50: 49 | C50: 1 [Super Cool 1, Salvage 4, -1 Corner Speed Limit] | D50: 2 | E50: D | F50: 4000000
...

Sheet Upgrade Tracker
A1: UPGRADE TRACKER — CURRENT SEASON
A2: Rule: One upgrade per type only (one Engine, one Tires, one Aero, one Cooling, one Fuel System, one Chassis). No stacking.
A4: Driver | B4: Sponsor | C4: Budget | D4: Upgrade 1 | E4: Upgrade 2 | F4: Upgrade 3 | G4: Upgrade 4 | H4: Upgrade 5 | I4: Upgrade 6 | J4: Upgrade 7 | K4: Modification | L4: Remaining Budget
A5: {=INDEX(DriverLineup[Driver], ROW()-ROW($A$5)+1)} -> Anders Snabb | B5: Noctie | C5: {=SUM('1961 Season Overview'!$B$10, XLOOKUP(B5, SponsorInventory[Sponsor], SponsorInventory[Funding], 0))+K5} -> 17000000 | D5: 60 | E5: 42 | F5: 36 | K5: 0 | L5: {=C5-XLOOKUP(D5, UpgradeInventory[Part Number], UpgradeInventory[Cost], 0)-XLOOKUP(E5, UpgradeInventory[Part Number], UpgradeInventory[Cost], 0)-XLOOKUP(F5, UpgradeInventory[Part Number], UpgradeInventory[Cost], 0)-XLOOKUP(G5, UpgradeInventory[Part Number], UpgradeInventory[Cost], 0)-XLOOKUP(H5, UpgradeInventory[Part Number], UpgradeInventory[Cost], 0)-XLOOKUP(I5, UpgradeInventory[Part Number], UpgradeInventory[Cost], 0)-XLOOKUP(J5, UpgradeInventory[Part Number], UpgradeInventory[Cost], 0)} -> 2500000
A6: {=INDEX(DriverLineup[Driver], ROW()-ROW($A$5)+1)} -> Count Dragula | B6: E. Mercury Air System | C6: {=SUM('1961 Season Overview'!$B$10, XLOOKUP(B6, SponsorInventory[Sponsor], SponsorInventory[Funding], 0))+K6} -> 16000000 | D6: 13 | E6: 37 | F6: 49 | K6: -1000000 | L6: {=C6-XLOOKUP(D6, UpgradeInventory[Part Number], UpgradeInventory[Cost], 0)-XLOOKUP(E6, UpgradeInventory[Part Number], UpgradeInventory[Cost], 0)-XLOOKUP(F6, UpgradeInventory[Part Number], UpgradeInventory[Cost], 0)-XLOOKUP(G6, UpgradeInventory[Part Number], UpgradeInventory[Cost], 0)-XLOOKUP(H6, UpgradeInventory[Part Number], UpgradeInventory[Cost], 0)-XLOOKUP(I6, UpgradeInventory[Part Number], UpgradeInventory[Cost], 0)-XLOOKUP(J6, UpgradeInventory[Part Number], UpgradeInventory[Cost], 0)} -> 500000
A7: {=INDEX(DriverLineup[Driver], ROW()-ROW($A$5)+1)} -> Horace Bauer | B7: Beewee | C7: {=SUM('1961 Season Overview'!$B$10, XLOOKUP(B7, SponsorInventory[Sponsor], SponsorInventory[Funding], 0))+K7} -> 17000000 | D7: 38 | E7: 3 | F7: 46 | L7: {=C7-XLOOKUP(D7, UpgradeInventory[Part Number], UpgradeInventory[Cost], 0)-XLOOKUP(E7, UpgradeInventory[Part Number], UpgradeInventory[Cost], 0)-XLOOKUP(F7, UpgradeInventory[Part Number], UpgradeInventory[Cost], 0)-XLOOKUP(G7, UpgradeInventory[Part Number], UpgradeInventory[Cost], 0)-XLOOKUP(H7, UpgradeInventory[Part Number], UpgradeInventory[Cost], 0)-XLOOKUP(I7, UpgradeInventory[Part Number], UpgradeInventory[Cost], 0)-XLOOKUP(J7, UpgradeInventory[Part Number], UpgradeInventory[Cost], 0)} -> 0
A8: {=INDEX(DriverLineup[Driver], ROW()-ROW($A$5)+1)} -> Jean Girard | B8: Lord & CO | C8: {=SUM('1961 Season Overview'!$B$10, XLOOKUP(B8, SponsorInventory[Sponsor], SponsorInventory[Funding], 0))+K8} -> 17000000 | D8: 27 | E8: 38 | F8: 42 | L8: {=C8-XLOOKUP(D8, UpgradeInventory[Part Number], UpgradeInventory[Cost], 0)-XLOOKUP(E8, UpgradeInventory[Part Number], UpgradeInventory[Cost], 0)-XLOOKUP(F8, UpgradeInventory[Part Number], UpgradeInventory[Cost], 0)-XLOOKUP(G8, UpgradeInventory[Part Number], UpgradeInventory[Cost], 0)-XLOOKUP(H8, UpgradeInventory[Part Number], UpgradeInventory[Cost], 0)-XLOOKUP(I8, UpgradeInventory[Part Number], UpgradeInventory[Cost], 0)-XLOOKUP(J8, UpgradeInventory[Part Number], UpgradeInventory[Cost], 0)} -> 0
A9: {=INDEX(DriverLineup[Driver], ROW()-ROW($A$5)+1)} -> "Caveman" Dale Mercer | B9: Dramdo | C9: {=SUM('1961 Season Overview'!$B$10, XLOOKUP(B9, SponsorInventory[Sponsor], SponsorInventory[Funding], 0))+K9} -> 18000000 | D9: 40 | E9: 46 | F9: 6 | L9: {=C9-XLOOKUP(D9, UpgradeInventory[Part Number], UpgradeInventory[Cost], 0)-XLOOKUP(E9, UpgradeInventory[Part Number], UpgradeInventory[Cost], 0)-XLOOKUP(F9, UpgradeInventory[Part Number], UpgradeInventory[Cost], 0)-XLOOKUP(G9, UpgradeInventory[Part Number], UpgradeInventory[Cost], 0)-XLOOKUP(H9, UpgradeInventory[Part Number], UpgradeInventory[Cost], 0)-XLOOKUP(I9, UpgradeInventory[Part Number], UpgradeInventory[Cost], 0)-XLOOKUP(J9, UpgradeInventory[Part Number], UpgradeInventory[Cost], 0)} -> 1500000
A10: {=INDEX(DriverLineup[Driver], ROW()-ROW($A$5)+1)} -> Circe Belladonna | B10: De Angeli | C10: {=SUM('1961 Season Overview'!$B$10, XLOOKUP(B10, SponsorInventory[Sponsor], SponsorInventory[Funding], 0))+K10} -> 23000000 | D10: 27 | E10: 60 | F10: 36 | K10: 4000000 | L10: {=C10-XLOOKUP(D10, UpgradeInventory[Part Number], UpgradeInventory[Cost], 0)-XLOOKUP(E10, UpgradeInventory[Part Number], UpgradeInventory[Cost], 0)-XLOOKUP(F10, UpgradeInventory[Part Number], UpgradeInventory[Cost], 0)-XLOOKUP(G10, UpgradeInventory[Part Number], UpgradeInventory[Cost], 0)-XLOOKUP(H10, UpgradeInventory[Part Number], UpgradeInventory[Cost], 0)-XLOOKUP(I10, UpgradeInventory[Part Number], UpgradeInventory[Cost], 0)-XLOOKUP(J10, UpgradeInventory[Part Number], UpgradeInventory[Cost], 0)} -> 6500000
A11: {=INDEX(DriverLineup[Driver], ROW()-ROW($A$5)+1)} -> Mr. Pink | B11: Eole Wing Industries | C11: {=SUM('1961 Season Overview'!$B$10, XLOOKUP(B11, SponsorInventory[Sponsor], SponsorInventory[Funding], 0))+K11} -> 19000000 | D11: 66 | E11: 18 | F11: 25 | K11: 3000000 | L11: {=C11-XLOOKUP(D11, UpgradeInventory[Part Number], UpgradeInventory[Cost], 0)-XLOOKUP(E11, UpgradeInventory[Part Number], UpgradeInventory[Cost], 0)-XLOOKUP(F11, UpgradeInventory[Part Number], UpgradeInventory[Cost], 0)-XLOOKUP(G11, UpgradeInventory[Part Number], UpgradeInventory[Cost], 0)-XLOOKUP(H11, UpgradeInventory[Part Number], UpgradeInventory[Cost], 0)-XLOOKUP(I11, UpgradeInventory[Part Number], UpgradeInventory[Cost], 0)-XLOOKUP(J11, UpgradeInventory[Part Number], UpgradeInventory[Cost], 0)} -> 0
A12: {=INDEX(DriverLineup[Driver], ROW()-ROW($A$5)+1)} -> Chico Suave | B12: Fredo&F | C12: {=SUM('1961 Season Overview'!$B$10, XLOOKUP(B12, SponsorInventory[Sponsor], SponsorInventory[Funding], 0))+K12} -> 21000000 | D12: 6 | E12: 7 | F12: 39 | K12: 3000000 | L12: {=C12-XLOOKUP(D12, UpgradeInventory[Part Number], UpgradeInventory[Cost], 0)-XLOOKUP(E12, UpgradeInventory[Part Number], UpgradeInventory[Cost], 0)-XLOOKUP(F12, UpgradeInventory[Part Number], UpgradeInventory[Cost], 0)-XLOOKUP(G12, UpgradeInventory[Part Number], UpgradeInventory[Cost], 0)-XLOOKUP(H12, UpgradeInventory[Part Number], UpgradeInventory[Cost], 0)-XLOOKUP(I12, UpgradeInventory[Part Number], UpgradeInventory[Cost], 0)-XLOOKUP(J12, UpgradeInventory[Part Number], UpgradeInventory[Cost], 0)} -> 14000000
A14: UPGRADE TYPE LEGEND
A15: Turbo Charger | B15: Speed and acceleration upgrades
A16: Tires | B16: Grip, handling, and wear management
A17: Aerodynamics | B17: Downforce and drag reduction
A18: Cooling | B18: Heat management, prevents overheating
A19: Fuel System | B19: Fuel efficiency and range
A20: Chassis | B20: Structural rigidity and weight

Sheet Hall of Fame
A1: HALL OF FAME — LIFETIME CAMPAIGN STATS
A15: SEASON-BY-SEASON CHAMPION LOG
A17: 1
A18: 2
A19: 3
A20: 4
A21: 5
A22: 6
A23: 7
A24: 8
A25: 9
A26: 10
A28: MISSED RACE LOG

Sheet Off-Season Budget
A1: OFF-SEASON UPGRADE BUDGET — CATCH-UP SYSTEM
A3: Offseason Development Regulations
D4: Winnings
A5: Champion (1) | B5: May exchange one upgrade card | C5: No extra heat cards | D5: 10000000
A6: Top half (2-4) | B6: May exchange one upgrade card | C6: No extra heat cards | D6: 2 - $7,000,000 3 - $6,000,000 4 - $5,000,000
A7: Bottom half (5-7) | B7: May exchange two upgrade cards | C7: Gets one extra heat upgrade card for next season | D7: 2000000
A8: Last place (8) | B8: Can exchange all or any number of upgrade cards | C8: Gets one extra heat upgrade card for next season | D8: 0
A11: DRIVER OFF-SEASON TRACKER
A22: MID-SEASON UPGRADE WINDOW
